<robot name="onshape">
<link name="base_link">
<visual>
<origin xyz="0 0 0" rpy="0 -0 0" />
<geometry>
<mesh filename="meshes/base_link.stl"/>
</geometry>
<material name="base_link_material">
<color rgba="0.19607843137254901689 0.43921568627450979783 0.078431372549019606755 1.0"/>
</material>
</visual>
<collision>
<origin xyz="0 0 0" rpy="0 -0 0" />
<geometry>
<mesh filename="meshes/base_link.stl"/>
</geometry>
</collision>
<inertial>
<origin xyz="-0.0038912060641234204675 0.94417835578650088912 0.70159558953869916031" rpy="0 0 0"/>
<mass value="1499.9999999999993179" />
<inertia ixx="3977.710599158952391" ixy="2.4359446062355916141"  ixz="-0.23812520616698054643" iyy="879.41162393756735582" iyz="164.77461570684388903" izz="4496.6843394325978807" />
</inertial>
</link>

<link name="cranepillar">
<visual>
<origin xyz="6.9388939039072283776e-18 -1.9749999999999998668 1.8000000000000002665" rpy="3.141592653589793116 1.6940658945086006781e-21 2.516552257085389921e-18" />
<geometry>
<mesh filename="meshes/cranepillar.stl"/>
</geometry>
<material name="cranepillar_material">
<color rgba="0.98039215686274505668 0.71372549019607844922 0.0039215686274509803377 1.0"/>
</material>
</visual>
<collision>
<origin xyz="6.9388939039072283776e-18 -1.9749999999999998668 1.8000000000000002665" rpy="3.141592653589793116 1.6940658945086006781e-21 2.516552257085389921e-18" />
<geometry>
<mesh filename="meshes/cranepillar.stl"/>
</geometry>
</collision>
<inertial>
<origin xyz="6.5177737211082862288e-08 0.069996065189212197666 -0.40871146584034484528" rpy="0 0 0"/>
<mass value="158.26819918446105362" />
<inertia ixx="20.304254714215375088" ixy="3.9605699781677006395e-06"  ixz="-8.1723973261701671507e-07" iyy="19.504224403354090356" iyz="3.0542376148195309327" izz="2.5286420750194498197" />
</inertial>
</link>

<link name="cranearm">
<visual>
<origin xyz="2.1631691341646699378 2.9071014878752601263 0.10714734974687092905" rpy="1.57079632679489678 1.5707963267948961139 0" />
<geometry>
<mesh filename="meshes/cranearm.stl"/>
</geometry>
<material name="cranearm_material">
<color rgba="0.98039215686274505668 0.71372549019607844922 0.0039215686274509803377 1.0"/>
</material>
</visual>
<collision>
<origin xyz="2.1631691341646699378 2.9071014878752601263 0.10714734974687092905" rpy="1.57079632679489678 1.5707963267948961139 0" />
<geometry>
<mesh filename="meshes/cranearm.stl"/>
</geometry>
</collision>
<inertial>
<origin xyz="1.4710758781849475607 -0.83447497357367239612 0.11000015269846499799" rpy="0 0 0"/>
<mass value="171.36007144775499" />
<inertia ixx="31.174403809260475384" ixy="53.72154790670983715"  ixz="-2.3471090249550919692e-06" iyy="103.78227622883770209" iyz="2.968750295156902758e-06" izz="132.11938151457613344" />
</inertial>
</link>

<link name="extension_arm">
<visual>
<origin xyz="-0.088447174187276322854 -5.3839193952782498087 -0.06714734974682075308" rpy="-1.570796326794896558 -1.5707963267948796826 0" />
<geometry>
<mesh filename="meshes/extension_arm.stl"/>
</geometry>
<material name="extension_arm_material">
<color rgba="0.98039215686274505668 0.71372549019607844922 0.0039215686274509803377 1.0"/>
</material>
</visual>
<collision>
<origin xyz="-0.088447174187276322854 -5.3839193952782498087 -0.06714734974682075308" rpy="-1.570796326794896558 -1.5707963267948796826 0" />
<geometry>
<mesh filename="meshes/extension_arm.stl"/>
</geometry>
</collision>
<inertial>
<origin xyz="0.71945517939019365539 0.12523230339912849729 -0.10999999999999975075" rpy="0 0 0"/>
<mass value="132.70502483158344376" />
<inertia ixx="8.0714226307109129266" ixy="18.156198033664058045"  ixz="1.1028622219671950734e-14" iyy="63.582628627999859816" iyz="2.9983655832555437732e-14" izz="70.212133412086018325" />
</inertial>
</link>

<link name="extension">
<visual>
<origin xyz="0.097852650417088363199 5.3847096770111528841 1.5927817167852027502" rpy="1.8759826062349289622 -5.9213930349191567547e-15 1.3417001884508113519e-18" />
<geometry>
<mesh filename="meshes/extension.stl"/>
</geometry>
<material name="extension_material">
<color rgba="0.98039215686274505668 0.71372549019607844922 0.0039215686274509803377 1.0"/>
</material>
</visual>
<collision>
<origin xyz="0.097852650417088363199 5.3847096770111528841 1.5927817167852027502" rpy="1.8759826062349289622 -5.9213930349191567547e-15 1.3417001884508113519e-18" />
<geometry>
<mesh filename="meshes/extension.stl"/>
</geometry>
</collision>
<inertial>
<origin xyz="0.055000000489328113029 -0.11308667092188519343 1.1835917326395066773" rpy="0 0 0"/>
<mass value="74.483829935135759115" />
<inertia ixx="35.990982829721396286" ixy="2.8883683335390858708e-10"  ixz="4.53329415410387902e-09" iyy="35.493371181524160818" iyz="-0.96498947282822733484" izz="0.92591432257179961951" />
</inertial>
</link>

<link name="intermediatehookjnt">
<visual>
<origin xyz="1.1629408158115603911 -1.6924602990154093973 0.059999999999999990841" rpy="-1.570796326794896558 -1.570796326794896558 0" />
<geometry>
<mesh filename="meshes/intermediatehookjnt.stl"/>
</geometry>
<material name="intermediatehookjnt_material">
<color rgba="0.98039215686274505668 0.71372549019607844922 0.0039215686274509803377 1.0"/>
</material>
</visual>
<collision>
<origin xyz="1.1629408158115603911 -1.6924602990154093973 0.059999999999999990841" rpy="-1.570796326794896558 -1.570796326794896558 0" />
<geometry>
<mesh filename="meshes/intermediatehookjnt.stl"/>
</geometry>
</collision>
<inertial>
<origin xyz="7.2130032391370946243e-08 -0.1215916708469393509 0.059999999999999928391" rpy="0 0 0"/>
<mass value="6.6927523972674238806" />
<inertia ixx="0.072021619002840306378" ixy="2.6246446781931340384e-08"  ixz="-3.813379976753245862e-19" iyy="0.032102433616367866132" iyz="-6.769896028265984685e-21" izz="0.063250708421585463692" />
</inertial>
</link>

<link name="grapplehook">
<visual>
<origin xyz="1.1102230246251565404e-16 1.4599999999999995204 1.1229409087543604784" rpy="1.570796326794896558 -1.7347234759768070944e-18 0" />
<geometry>
<mesh filename="meshes/grapplehook.stl"/>
</geometry>
<material name="grapplehook_material">
<color rgba="0.98039215686274505668 0.71372549019607844922 0.0039215686274509803377 1.0"/>
</material>
</visual>
<collision>
<origin xyz="1.1102230246251565404e-16 1.4599999999999995204 1.1229409087543604784" rpy="1.570796326794896558 -1.7347234759768070944e-18 0" />
<geometry>
<mesh filename="meshes/grapplehook.stl"/>
</geometry>
</collision>
<inertial>
<origin xyz="9.6779365295442961279e-17 0.11889435836171992344 -0.039999999999999369393" rpy="0 0 0"/>
<mass value="11.69137300060207707" />
<inertia ixx="0.071283575399172696696" ixy="6.2153568335433644892e-19"  ixz="2.2920506233706871967e-20" iyy="0.044786365951232892657" iyz="0" izz="0.077427737510019634115" />
</inertial>
</link>

<link name="grapplebody">
<visual>
<origin xyz="0.002852650253129418445 -4.2941082490610078537 0.31050192853763469714" rpy="-0.83507352101469434213 8.8123952579621800396e-16 1.7347234759768070944e-18" />
<geometry>
<mesh filename="meshes/grapplebody.stl"/>
</geometry>
<material name="grapplebody_material">
<color rgba="0 0 0 1.0"/>
</material>
</visual>
<collision>
<origin xyz="0.002852650253129418445 -4.2941082490610078537 0.31050192853763469714" rpy="-0.83507352101469434213 8.8123952579621800396e-16 1.7347234759768070944e-18" />
<geometry>
<mesh filename="meshes/grapplebody.stl"/>
</geometry>
</collision>
<inertial>
<origin xyz="-0.0046191934757198547384 -8.4376949871511897072e-15 -0.14258886664155800972" rpy="0 0 0"/>
<mass value="100.00000000000002842" />
<inertia ixx="2.2032827057151145311" ixy="3.0196331546328281092e-14"  ixz="-0.01440316534977603008" iyy="5.1544932520305346557" iyz="-1.5987211554602254182e-14" izz="5.9229805801947446042" />
</inertial>
</link>

<link name="grappler_1">
<visual>
<origin xyz="0.32285265025312614995 3.4005112229779843602 3.4245452734591577126" rpy="-3.1412275799297373347 -4.4495657158805101972e-16 -6.9388939039072283776e-18" />
<geometry>
<mesh filename="meshes/grappler_1.stl"/>
</geometry>
<material name="grappler_1_material">
<color rgba="0.98039215686274505668 0.71372549019607844922 0.0039215686274509803377 1.0"/>
</material>
</visual>
<collision>
<origin xyz="0.32285265025312614995 3.4005112229779843602 3.4245452734591577126" rpy="-3.1412275799297373347 -4.4495657158805101972e-16 -6.9388939039072283776e-18" />
<geometry>
<mesh filename="meshes/grappler_1.stl"/>
</geometry>
</collision>
<inertial>
<origin xyz="-0.03598028436155475962 0.039724540553617675165 0.14108446211637071244" rpy="0 0 0"/>
<mass value="39.999999999999872102" />
<inertia ixx="3.6544012783942796396" ixy="-0.17169040574983288061"  ixz="0.016409580184274151493" iyy="3.552359250722708861" iyz="0.061201795792073895863" izz="0.68809115739437054504" />
</inertial>
</link>

<link name="grappler_2">
<visual>
<origin xyz="0.52178390116212325367 -3.5495452734592136679 3.5464990784749854669" rpy="-1.5704312531348409987 -6.8001160258290838101e-16 -5.6378512969246230568e-18" />
<geometry>
<mesh filename="meshes/grappler_2.stl"/>
</geometry>
<material name="grappler_2_material">
<color rgba="0.98039215686274505668 0.71372549019607844922 0.0039215686274509803377 1.0"/>
</material>
</visual>
<collision>
<origin xyz="0.52178390116212325367 -3.5495452734592136679 3.5464990784749854669" rpy="-1.5704312531348409987 -6.8001160258290838101e-16 -5.6378512969246230568e-18" />
<geometry>
<mesh filename="meshes/grappler_2.stl"/>
</geometry>
</collision>
<inertial>
<origin xyz="-0.03616514622736755058 -2.9753977059954195283e-14 -0.11542357832264553419" rpy="0 0 0"/>
<mass value="0.10000000000000008882" />
<inertia ixx="0.001419938581217723185" ixy="2.9873058722091157995e-17"  ixz="-9.0443344469136782758e-05" iyy="0.0006137732400707944817" iyz="-1.3553347719236458029e-17" izz="0.00098009656545995854984" />
</inertial>
</link>

<link name="grappler_3">
<visual>
<origin xyz="0.56432035077736664164 -3.549545273459199457 3.7964990784749854669" rpy="-1.5704312531348409987 -6.8001160258290818379e-16 -8.2399365108898321577e-18" />
<geometry>
<mesh filename="meshes/grappler_3.stl"/>
</geometry>
<material name="grappler_3_material">
<color rgba="0.98039215686274505668 0.71372549019607844922 0.0039215686274509803377 1.0"/>
</material>
</visual>
<collision>
<origin xyz="0.56432035077736664164 -3.549545273459199457 3.7964990784749854669" rpy="-1.5704312531348409987 -6.8001160258290818379e-16 -8.2399365108898321577e-18" />
<geometry>
<mesh filename="meshes/grappler_3.stl"/>
</geometry>
</collision>
<inertial>
<origin xyz="0.05264441572777567302 -1.7319479184152442031e-14 -0.11903215134654279717" rpy="0 0 0"/>
<mass value="0.10000000000000003331" />
<inertia ixx="0.001110362332617847482" ixy="2.1888813664708815787e-17"  ixz="0.00025300744770991300545" iyy="0.00059669206907971852026" iyz="1.3035704709345673734e-17" izz="0.00082889974619581479384" />
</inertial>
</link>

<joint name="Fastened 2" type="fixed">
<origin xyz="-0.042536449615243610012 -1.7763568394002504647e-14 -0.24999999999999955591" rpy="-1.0533240946131242097e-14 -0 -4.3368086899420995881e-19" />
<parent link="grappler_2" />
<child link="grappler_3" />
<axis xyz="0 0 1"/>
<limit effort="5e5" velocity="20" />
<joint_properties friction="0.0"/>
</joint>

<joint name="Fastened 1" type="fixed">
<origin xyz="-0.19893125090899821394 -0.14598785549699977437 -0.12500000000005534462" rpy="-1.570796326794896558 -4.527628272299409324e-16 -6.8001160258289980215e-16" />
<parent link="grappler_1" />
<child link="grappler_2" />
<axis xyz="0 0 1"/>
<limit effort="5e5" velocity="20" />
<joint_properties friction="0.0"/>
</joint>

<link name="grappler_2_2">
<visual>
<origin xyz="0.52178390116212280958 -3.5495452734592118915 3.5464990784749850228" rpy="-1.5704312531348409987 -6.8695049648681560939e-16 -2.168404344971008868e-18" />
<geometry>
<mesh filename="meshes/grappler_2.stl"/>
</geometry>
<material name="grappler_2_material">
<color rgba="0.98039215686274505668 0.71372549019607844922 0.0039215686274509803377 1.0"/>
</material>
</visual>
<collision>
<origin xyz="0.52178390116212280958 -3.5495452734592118915 3.5464990784749850228" rpy="-1.5704312531348409987 -6.8695049648681560939e-16 -2.168404344971008868e-18" />
<geometry>
<mesh filename="meshes/grappler_2.stl"/>
</geometry>
</collision>
<inertial>
<origin xyz="-0.036165146227367994669 -2.8421709430404007435e-14 -0.11542357832264642237" rpy="0 0 0"/>
<mass value="0.10000000000000008882" />
<inertia ixx="0.001419938581217723185" ixy="2.9866474364415235895e-17"  ixz="-9.0443344469136782758e-05" iyy="0.00061377324007079437328" iyz="-1.3567297293086552287e-17" izz="0.00098009656545995898352" />
</inertial>
</link>

<link name="grappler_3_2">
<visual>
<origin xyz="0.56432035077736708573 -3.549545273459199457 3.7964990784749854669" rpy="-1.5704312531348409987 -6.8001160258290818379e-16 -8.6736173798840335461e-19" />
<geometry>
<mesh filename="meshes/grappler_3.stl"/>
</geometry>
<material name="grappler_3_material">
<color rgba="0.98039215686274505668 0.71372549019607844922 0.0039215686274509803377 1.0"/>
</material>
</visual>
<collision>
<origin xyz="0.56432035077736708573 -3.549545273459199457 3.7964990784749854669" rpy="-1.5704312531348409987 -6.8001160258290818379e-16 -8.6736173798840335461e-19" />
<geometry>
<mesh filename="meshes/grappler_3.stl"/>
</geometry>
</collision>
<inertial>
<origin xyz="0.052644415727776117109 -1.7763568394002507802e-14 -0.11903215134654328289" rpy="0 0 0"/>
<mass value="0.10000000000000003331" />
<inertia ixx="0.001110362332617847482" ixy="2.1894478197543578921e-17"  ixz="0.00025300744770991305966" iyy="0.00059669206907971841184" iyz="1.3017678789436918155e-17" izz="0.00082889974619581501068" />
</inertial>
</link>

<joint name="Fastened 4" type="fixed">
<origin xyz="-0.042536449615243610012 -1.7097434579227410723e-14 -0.24999999999999911182" rpy="-1.0560996521746880477e-14 6.9388939039073608816e-18 4.3368086899421001658e-18" />
<parent link="grappler_2_2" />
<child link="grappler_3_2" />
<axis xyz="0 0 1"/>
<limit effort="5e5" velocity="20" />
<joint_properties friction="0.0"/>
</joint>

<joint name="Fastened 3" type="fixed">
<origin xyz="-0.19893125090893448714 -0.14598785549700021846 0.42499999999986720622" rpy="-1.570796326794896558 -4.5319650809893493696e-16 -6.9388939039071376586e-16" />
<parent link="grappler_1" />
<child link="grappler_2_2" />
<axis xyz="0 0 1"/>
<limit effort="5e5" velocity="20" />
<joint_properties friction="0.0"/>
</joint>

<joint name="Revolute 7" type="revolute">
<origin xyz="-0.28000000000000069278 0.15000000000000096589 -0.17376999257947289834" rpy="1.570796326794896558 -0.0012391264808447304685 -2.3158576183525763738e-16" />
<parent link="grapplebody" />
<child link="grappler_1" />
<axis xyz="0 0 1"/>
<limit effort="5e5" velocity="20" />
<joint_properties friction="0.0"/>
</joint>

<link name="grapplel_1">
<visual>
<origin xyz="-0.23714734974687345925 3.4005112229779794752 3.4295452734591558297" rpy="-3.1412275799297373347 -4.3281350725621341936e-16 0" />
<geometry>
<mesh filename="meshes/grapplel_1.stl"/>
</geometry>
<material name="grapplel_1_material">
<color rgba="0.98039215686274505668 0.71372549019607844922 0.0039215686274509803377 1.0"/>
</material>
</visual>
<collision>
<origin xyz="-0.23714734974687345925 3.4005112229779794752 3.4295452734591558297" rpy="-3.1412275799297373347 -4.3281350725621341936e-16 0" />
<geometry>
<mesh filename="meshes/grapplel_1.stl"/>
</geometry>
</collision>
<inertial>
<origin xyz="0.037443654443467450088 0.034176353076496038264 0.13906290274925314776" rpy="0 0 0"/>
<mass value="40.000000000000113687" />
<inertia ixx="3.5564629020681217675" ixy="0.1738675092252753851"  ixz="-0.02077058182301448272" iyy="3.4587801547719605466" iyz="0.074727970863875670116" izz="0.65771533444672147795" />
</inertial>
</link>

<link name="grapplel_2">
<visual>
<origin xyz="-0.43813173477880873463 -3.5495452734591621535 3.5514990784749884689" rpy="-1.5704312531348407767 2.8449465006019636348e-15 6.505213034913026604e-18" />
<geometry>
<mesh filename="meshes/grapplel_2.stl"/>
</geometry>
<material name="grapplel_2_material">
<color rgba="0.98039215686274505668 0.71372549019607844922 0.0039215686274509803377 1.0"/>
</material>
</visual>
<collision>
<origin xyz="-0.43813173477880873463 -3.5495452734591621535 3.5514990784749884689" rpy="-1.5704312531348407767 2.8449465006019636348e-15 6.505213034913026604e-18" />
<geometry>
<mesh filename="meshes/grapplel_2.stl"/>
</geometry>
</collision>
<inertial>
<origin xyz="0.032775946233430164334 3.3306690738754696213e-14 -0.11517479281854796358" rpy="0 0 0"/>
<mass value="0.10000000000000003331" />
<inertia ixx="0.0013183426952416842266" ixy="-2.9003126106758939638e-17"  ixz="7.7832435127564374264e-05" iyy="0.00058918513895291665505" iyz="5.0093475561060118659e-17" izz="0.00085507882678280573967" />
</inertial>
</link>

<link name="grapplel_3">
<visual>
<origin xyz="-0.47428278211786123464 -3.5495452734591923516 3.8014990784749831398" rpy="-1.5704312531348407767 2.8449465006019636348e-15 -2.6020852139652106416e-18" />
<geometry>
<mesh filename="meshes/grapplel_3.stl"/>
</geometry>
<material name="grapplel_3_material">
<color rgba="0.98039215686274505668 0.71372549019607844922 0.0039215686274509803377 1.0"/>
</material>
</visual>
<collision>
<origin xyz="-0.47428278211786123464 -3.5495452734591923516 3.8014990784749831398" rpy="-1.5704312531348407767 2.8449465006019636348e-15 -2.6020852139652106416e-18" />
<geometry>
<mesh filename="meshes/grapplel_3.stl"/>
</geometry>
</collision>
<inertial>
<origin xyz="-0.04904639767159579139 3.1974423109204508364e-14 -0.11025446657680998408" rpy="0 0 0"/>
<mass value="0.10000000000000001943" />
<inertia ixx="0.00096032338712582793628" ixy="1.2927944913098185628e-16"  ixz="-0.00021878726290633390109" iyy="0.00051582057558843959991" iyz="-3.6037440257407835076e-17" izz="0.00070455456053961540604" />
</inertial>
</link>

<joint name="Fastened 6" type="fixed">
<origin xyz="0.036151047339051611829 2.1704860131421810365e-14 -0.24999999999998889777" rpy="1.0616507672978198257e-14 -6.938893903907322363e-18 5.6378512969246993237e-18" />
<parent link="grapplel_2" />
<child link="grapplel_3" />
<axis xyz="0 0 1"/>
<limit effort="5e5" velocity="20" />
<joint_properties friction="0.0"/>
</joint>

<joint name="Fastened 5" type="fixed">
<origin xyz="0.20098438503194238081 -0.15098785549700011188 -0.11999999999999816369" rpy="-1.570796326794896558 -4.4018608202911100381e-16 2.8518853945058460141e-15" />
<parent link="grapplel_1" />
<child link="grapplel_2" />
<axis xyz="0 0 1"/>
<limit effort="5e5" velocity="20" />
<joint_properties friction="0.0"/>
</joint>

<link name="grapplel_2_2">
<visual>
<origin xyz="-0.43813173477880829054 -3.5495452734591621535 3.551499078474988913" rpy="-1.5704312531348407767 2.8449465006019640293e-15 6.0715321659188256008e-18" />
<geometry>
<mesh filename="meshes/grapplel_2.stl"/>
</geometry>
<material name="grapplel_2_material">
<color rgba="0.98039215686274505668 0.71372549019607844922 0.0039215686274509803377 1.0"/>
</material>
</visual>
<collision>
<origin xyz="-0.43813173477880829054 -3.5495452734591621535 3.551499078474988913" rpy="-1.5704312531348407767 2.8449465006019640293e-15 6.0715321659188256008e-18" />
<geometry>
<mesh filename="meshes/grapplel_2.stl"/>
</geometry>
</collision>
<inertial>
<origin xyz="0.032775946233430552912 3.3750779948604758829e-14 -0.11517479281854800521" rpy="0 0 0"/>
<mass value="0.10000000000000003331" />
<inertia ixx="0.001318342695241683793" ixy="-2.9000879484215245615e-17"  ixz="7.7832435127564374264e-05" iyy="0.00058918513895291687189" iyz="5.0085296399163194321e-17" izz="0.00085507882678280584809" />
</inertial>
</link>

<link name="grapplel_3_2">
<visual>
<origin xyz="-0.47428278211786123464 -3.5495452734591932398 3.8014990784749831398" rpy="-1.5704312531348407767 2.858824288409778486e-15 3.9031278209478167328e-18" />
<geometry>
<mesh filename="meshes/grapplel_3.stl"/>
</geometry>
<material name="grapplel_3_material">
<color rgba="0.98039215686274505668 0.71372549019607844922 0.0039215686274509803377 1.0"/>
</material>
</visual>
<collision>
<origin xyz="-0.47428278211786123464 -3.5495452734591932398 3.8014990784749831398" rpy="-1.5704312531348407767 2.858824288409778486e-15 3.9031278209478167328e-18" />
<geometry>
<mesh filename="meshes/grapplel_3.stl"/>
</geometry>
</collision>
<inertial>
<origin xyz="-0.04904639767159579139 3.1530333899354445748e-14 -0.11025446657680910978" rpy="0 0 0"/>
<mass value="0.10000000000000001943" />
<inertia ixx="0.00096032338712582771944" ixy="1.2928229463228903869e-16"  ixz="-0.00021878726290633381977" iyy="0.00051582057558843970833" iyz="-3.6019281988601071012e-17" izz="0.00070455456053961508078" />
</inertial>
</link>

<joint name="Fastened 8" type="fixed">
<origin xyz="0.036151047339052055918 2.1760371282653068192e-14 -0.24999999999998934186" rpy="1.0644263248593787728e-14 -6.9388939039073146593e-18 8.2399365108899369283e-18" />
<parent link="grapplel_2_2" />
<child link="grapplel_3_2" />
<axis xyz="0 0 1"/>
<limit effort="5e5" velocity="20" />
<joint_properties friction="0.0"/>
</joint>

<joint name="Fastened 7" type="fixed">
<origin xyz="0.20098438503192372906 -0.15098785549700677322 0.41999999999993625766" rpy="-1.570796326794896558 -4.4408920985005926351e-16 2.8518853945058491695e-15" />
<parent link="grapplel_1" />
<child link="grapplel_2_2" />
<axis xyz="0 0 1"/>
<limit effort="5e5" velocity="20" />
<joint_properties friction="0.0"/>
</joint>

<joint name="Revolute 8" type="revolute">
<origin xyz="0.28000000000000024869 0.1499999999999950262 -0.17376999257946490474" rpy="1.570796326794896558 -0.0012392036796337652007 -1.1071881086553791878e-15" />
<parent link="grapplebody" />
<child link="grapplel_1" />
<axis xyz="0 0 1"/>
<limit effort="5e5" velocity="20" />
<joint_properties friction="0.0"/>
</joint>

<joint name="Revolute 6" type="revolute">
<origin xyz="-8.3266726846886740532e-16 0.21499987652526808546 -0.039999999999999591438" rpy="-1.5707963267948972241 -1.4922776003255655564 -3.141592653589698525" />
<parent link="grapplehook" />
<child link="grapplebody" />
<axis xyz="0 0 1"/>
<limit effort="5e5" velocity="20" />
<joint_properties friction="0.0"/>
</joint>

<joint name="Revolute 5" type="revolute">
<origin xyz="0.039999907057202133132 -0.23246029901540588014 0.059999999999999859002" rpy="1.5707963267948958919 -1.4888182497545214833 1.5707963267948010788" />
<parent link="intermediatehookjnt" />
<child link="grapplehook" />
<axis xyz="0 0 1"/>
<limit effort="5e5" velocity="20" />
<joint_properties friction="0.0"/>
</joint>

<joint name="Revolute 4" type="revolute">
<origin xyz="-0.0049999998361772921007 -0.00046421498847237785412 2.3755713282784647333" rpy="-1.5707963267948956698 -1.0345551331654925242 -1.5707963267949169861" />
<parent link="extension" />
<child link="intermediatehookjnt" />
<axis xyz="0 0 1"/>
<limit effort="5e5" velocity="20" />
<joint_properties friction="0.0"/>
</joint>

<joint name="Slider 1" type="prismatic">
<origin xyz="0.48742141322008514237 0.064525742858752899167 -0.18000000000000238032" rpy="2.836406374149756271 -1.5707963267948803487 0" />
<parent link="extension_arm" />
<child link="extension" />
<axis xyz="0 0 1"/>
<limit effort="1" velocity="20" lower="-1.5" upper="0"/>
<joint_properties friction="0.0"/>
</joint>

<joint name="Revolute 3" type="revolute">
<origin xyz="2.9692039480166640963 -1.5997177007333398535 4.9960036108132044319e-16" rpy="3.1415926535897922278 2.3450022441440946277e-15 0.68296337307737620126" />
<parent link="cranearm" />
<child link="extension_arm" />
<axis xyz="0 0 1"/>
<limit effort="5e5" velocity="20" />
<joint_properties friction="0.0"/>
</joint>

<joint name="Revolute 2" type="revolute">
<origin xyz="0.11000000000000004219 0.17499999999999960032 -1.1000000000000025313" rpy="1.570796326794896558 0.4983570351858245262 -1.5707963267948956698" />
<parent link="cranepillar" />
<child link="cranearm" />
<axis xyz="0 0 1"/>
<limit effort="5e5" velocity="20" />
<joint_properties friction="0.0"/>
</joint>

<joint name="Revolute 1" type="revolute">
<origin xyz="-0.0028526502531802042095 -1.9808771680306498375 1.7659041313870393886" rpy="3.141227727442737816 -1.0377112517032391085e-05 -0.028428536727887490643" />
<parent link="base_link" />
<child link="cranepillar" />
<axis xyz="0 0 1"/>
<limit effort="5e5" velocity="20" />
<joint_properties friction="0.0"/>
</joint>


</robot>
